2024-09-22 18:13:39,165 - ERROR - An error occurred: Authentication (sqlalchemy.dialects.postgresql.asyncpg.ProgrammingError) <class 'asyncpg.exceptions.InsufficientPrivilegeError'>: permission denied for table users
[SQL: SELECT users.id, users.email, users.user_name, users.password, users.avatar, users.created_at, users.verified, users.token_verify, users.refresh_token, users.role, users.blocked, users.password_changed, users.company_id, users.active, users.description 
FROM users 
WHERE users.email = $1::VARCHAR]
[parameters: ('nevojt@gmail.com',)]
(Background on this error at: https://sqlalche.me/e/20/f405)
Traceback (most recent call last):
  File "/home/dmytro/company/api/venv/lib/python3.12/site-packages/sqlalchemy/dialects/postgresql/asyncpg.py", line 538, in _prepare_and_execute
    self._rows = deque(await prepared_stmt.fetch(*parameters))
                       ^^^^^^^^^^^^^^^^^^^^^^^^^^^^^^^^^^^^^^
  File "/home/dmytro/company/api/venv/lib/python3.12/site-packages/asyncpg/prepared_stmt.py", line 176, in fetch
    data = await self.__bind_execute(args, 0, timeout)
           ^^^^^^^^^^^^^^^^^^^^^^^^^^^^^^^^^^^^^^^^^^^
  File "/home/dmytro/company/api/venv/lib/python3.12/site-packages/asyncpg/prepared_stmt.py", line 241, in __bind_execute
    data, status, _ = await self.__do_execute(
                      ^^^^^^^^^^^^^^^^^^^^^^^^
  File "/home/dmytro/company/api/venv/lib/python3.12/site-packages/asyncpg/prepared_stmt.py", line 230, in __do_execute
    return await executor(protocol)
           ^^^^^^^^^^^^^^^^^^^^^^^^
  File "asyncpg/protocol/protocol.pyx", line 207, in bind_execute
asyncpg.exceptions.InsufficientPrivilegeError: permission denied for table users

The above exception was the direct cause of the following exception:

Traceback (most recent call last):
  File "/home/dmytro/company/api/venv/lib/python3.12/site-packages/sqlalchemy/engine/base.py", line 1967, in _exec_single_context
    self.dialect.do_execute(
  File "/home/dmytro/company/api/venv/lib/python3.12/site-packages/sqlalchemy/engine/default.py", line 924, in do_execute
    cursor.execute(statement, parameters)
  File "/home/dmytro/company/api/venv/lib/python3.12/site-packages/sqlalchemy/dialects/postgresql/asyncpg.py", line 572, in execute
    self._adapt_connection.await_(
  File "/home/dmytro/company/api/venv/lib/python3.12/site-packages/sqlalchemy/util/_concurrency_py3k.py", line 132, in await_only
    return current.parent.switch(awaitable)  # type: ignore[no-any-return,attr-defined] # noqa: E501
           ^^^^^^^^^^^^^^^^^^^^^^^^^^^^^^^^
  File "/home/dmytro/company/api/venv/lib/python3.12/site-packages/sqlalchemy/util/_concurrency_py3k.py", line 196, in greenlet_spawn
    value = await result
            ^^^^^^^^^^^^
  File "/home/dmytro/company/api/venv/lib/python3.12/site-packages/sqlalchemy/dialects/postgresql/asyncpg.py", line 550, in _prepare_and_execute
    self._handle_exception(error)
  File "/home/dmytro/company/api/venv/lib/python3.12/site-packages/sqlalchemy/dialects/postgresql/asyncpg.py", line 501, in _handle_exception
    self._adapt_connection._handle_exception(error)
  File "/home/dmytro/company/api/venv/lib/python3.12/site-packages/sqlalchemy/dialects/postgresql/asyncpg.py", line 784, in _handle_exception
    raise translated_error from error
sqlalchemy.dialects.postgresql.asyncpg.AsyncAdapt_asyncpg_dbapi.ProgrammingError: <class 'asyncpg.exceptions.InsufficientPrivilegeError'>: permission denied for table users

The above exception was the direct cause of the following exception:

Traceback (most recent call last):
  File "/home/dmytro/company/api/app/routers/user/auth.py", line 53, in login
    result = await db.execute(query)
             ^^^^^^^^^^^^^^^^^^^^^^^
  File "/home/dmytro/company/api/venv/lib/python3.12/site-packages/sqlalchemy/ext/asyncio/session.py", line 461, in execute
    result = await greenlet_spawn(
             ^^^^^^^^^^^^^^^^^^^^^
  File "/home/dmytro/company/api/venv/lib/python3.12/site-packages/sqlalchemy/util/_concurrency_py3k.py", line 201, in greenlet_spawn
    result = context.throw(*sys.exc_info())
             ^^^^^^^^^^^^^^^^^^^^^^^^^^^^^^
  File "/home/dmytro/company/api/venv/lib/python3.12/site-packages/sqlalchemy/orm/session.py", line 2351, in execute
    return self._execute_internal(
           ^^^^^^^^^^^^^^^^^^^^^^^
  File "/home/dmytro/company/api/venv/lib/python3.12/site-packages/sqlalchemy/orm/session.py", line 2236, in _execute_internal
    result: Result[Any] = compile_state_cls.orm_execute_statement(
                          ^^^^^^^^^^^^^^^^^^^^^^^^^^^^^^^^^^^^^^^^
  File "/home/dmytro/company/api/venv/lib/python3.12/site-packages/sqlalchemy/orm/context.py", line 293, in orm_execute_statement
    result = conn.execute(
             ^^^^^^^^^^^^^
  File "/home/dmytro/company/api/venv/lib/python3.12/site-packages/sqlalchemy/engine/base.py", line 1418, in execute
    return meth(
           ^^^^^
  File "/home/dmytro/company/api/venv/lib/python3.12/site-packages/sqlalchemy/sql/elements.py", line 515, in _execute_on_connection
    return connection._execute_clauseelement(
           ^^^^^^^^^^^^^^^^^^^^^^^^^^^^^^^^^^
  File "/home/dmytro/company/api/venv/lib/python3.12/site-packages/sqlalchemy/engine/base.py", line 1640, in _execute_clauseelement
    ret = self._execute_context(
          ^^^^^^^^^^^^^^^^^^^^^^
  File "/home/dmytro/company/api/venv/lib/python3.12/site-packages/sqlalchemy/engine/base.py", line 1846, in _execute_context
    return self._exec_single_context(
           ^^^^^^^^^^^^^^^^^^^^^^^^^^
  File "/home/dmytro/company/api/venv/lib/python3.12/site-packages/sqlalchemy/engine/base.py", line 1986, in _exec_single_context
    self._handle_dbapi_exception(
  File "/home/dmytro/company/api/venv/lib/python3.12/site-packages/sqlalchemy/engine/base.py", line 2353, in _handle_dbapi_exception
    raise sqlalchemy_exception.with_traceback(exc_info[2]) from e
  File "/home/dmytro/company/api/venv/lib/python3.12/site-packages/sqlalchemy/engine/base.py", line 1967, in _exec_single_context
    self.dialect.do_execute(
  File "/home/dmytro/company/api/venv/lib/python3.12/site-packages/sqlalchemy/engine/default.py", line 924, in do_execute
    cursor.execute(statement, parameters)
  File "/home/dmytro/company/api/venv/lib/python3.12/site-packages/sqlalchemy/dialects/postgresql/asyncpg.py", line 572, in execute
    self._adapt_connection.await_(
  File "/home/dmytro/company/api/venv/lib/python3.12/site-packages/sqlalchemy/util/_concurrency_py3k.py", line 132, in await_only
    return current.parent.switch(awaitable)  # type: ignore[no-any-return,attr-defined] # noqa: E501
           ^^^^^^^^^^^^^^^^^^^^^^^^^^^^^^^^
  File "/home/dmytro/company/api/venv/lib/python3.12/site-packages/sqlalchemy/util/_concurrency_py3k.py", line 196, in greenlet_spawn
    value = await result
            ^^^^^^^^^^^^
  File "/home/dmytro/company/api/venv/lib/python3.12/site-packages/sqlalchemy/dialects/postgresql/asyncpg.py", line 550, in _prepare_and_execute
    self._handle_exception(error)
  File "/home/dmytro/company/api/venv/lib/python3.12/site-packages/sqlalchemy/dialects/postgresql/asyncpg.py", line 501, in _handle_exception
    self._adapt_connection._handle_exception(error)
  File "/home/dmytro/company/api/venv/lib/python3.12/site-packages/sqlalchemy/dialects/postgresql/asyncpg.py", line 784, in _handle_exception
    raise translated_error from error
sqlalchemy.exc.ProgrammingError: (sqlalchemy.dialects.postgresql.asyncpg.ProgrammingError) <class 'asyncpg.exceptions.InsufficientPrivilegeError'>: permission denied for table users
[SQL: SELECT users.id, users.email, users.user_name, users.password, users.avatar, users.created_at, users.verified, users.token_verify, users.refresh_token, users.role, users.blocked, users.password_changed, users.company_id, users.active, users.description 
FROM users 
WHERE users.email = $1::VARCHAR]
[parameters: ('nevojt@gmail.com',)]
(Background on this error at: https://sqlalche.me/e/20/f405)
2024-09-22 18:21:48,673 - ERROR - An error occurred: Authentication (sqlalchemy.dialects.postgresql.asyncpg.ProgrammingError) <class 'asyncpg.exceptions.InsufficientPrivilegeError'>: permission denied for table users
[SQL: SELECT users.id, users.email, users.user_name, users.password, users.avatar, users.created_at, users.verified, users.token_verify, users.refresh_token, users.role, users.blocked, users.password_changed, users.company_id, users.active, users.description 
FROM users 
WHERE users.email = $1::VARCHAR]
[parameters: ('nevojt@gmail.com',)]
(Background on this error at: https://sqlalche.me/e/20/f405)
Traceback (most recent call last):
  File "/home/dmytro/company/api/venv/lib/python3.12/site-packages/sqlalchemy/dialects/postgresql/asyncpg.py", line 538, in _prepare_and_execute
    self._rows = deque(await prepared_stmt.fetch(*parameters))
                       ^^^^^^^^^^^^^^^^^^^^^^^^^^^^^^^^^^^^^^
  File "/home/dmytro/company/api/venv/lib/python3.12/site-packages/asyncpg/prepared_stmt.py", line 176, in fetch
    data = await self.__bind_execute(args, 0, timeout)
           ^^^^^^^^^^^^^^^^^^^^^^^^^^^^^^^^^^^^^^^^^^^
  File "/home/dmytro/company/api/venv/lib/python3.12/site-packages/asyncpg/prepared_stmt.py", line 241, in __bind_execute
    data, status, _ = await self.__do_execute(
                      ^^^^^^^^^^^^^^^^^^^^^^^^
  File "/home/dmytro/company/api/venv/lib/python3.12/site-packages/asyncpg/prepared_stmt.py", line 230, in __do_execute
    return await executor(protocol)
           ^^^^^^^^^^^^^^^^^^^^^^^^
  File "asyncpg/protocol/protocol.pyx", line 207, in bind_execute
asyncpg.exceptions.InsufficientPrivilegeError: permission denied for table users

The above exception was the direct cause of the following exception:

Traceback (most recent call last):
  File "/home/dmytro/company/api/venv/lib/python3.12/site-packages/sqlalchemy/engine/base.py", line 1967, in _exec_single_context
    self.dialect.do_execute(
  File "/home/dmytro/company/api/venv/lib/python3.12/site-packages/sqlalchemy/engine/default.py", line 924, in do_execute
    cursor.execute(statement, parameters)
  File "/home/dmytro/company/api/venv/lib/python3.12/site-packages/sqlalchemy/dialects/postgresql/asyncpg.py", line 572, in execute
    self._adapt_connection.await_(
  File "/home/dmytro/company/api/venv/lib/python3.12/site-packages/sqlalchemy/util/_concurrency_py3k.py", line 132, in await_only
    return current.parent.switch(awaitable)  # type: ignore[no-any-return,attr-defined] # noqa: E501
           ^^^^^^^^^^^^^^^^^^^^^^^^^^^^^^^^
  File "/home/dmytro/company/api/venv/lib/python3.12/site-packages/sqlalchemy/util/_concurrency_py3k.py", line 196, in greenlet_spawn
    value = await result
            ^^^^^^^^^^^^
  File "/home/dmytro/company/api/venv/lib/python3.12/site-packages/sqlalchemy/dialects/postgresql/asyncpg.py", line 550, in _prepare_and_execute
    self._handle_exception(error)
  File "/home/dmytro/company/api/venv/lib/python3.12/site-packages/sqlalchemy/dialects/postgresql/asyncpg.py", line 501, in _handle_exception
    self._adapt_connection._handle_exception(error)
  File "/home/dmytro/company/api/venv/lib/python3.12/site-packages/sqlalchemy/dialects/postgresql/asyncpg.py", line 784, in _handle_exception
    raise translated_error from error
sqlalchemy.dialects.postgresql.asyncpg.AsyncAdapt_asyncpg_dbapi.ProgrammingError: <class 'asyncpg.exceptions.InsufficientPrivilegeError'>: permission denied for table users

The above exception was the direct cause of the following exception:

Traceback (most recent call last):
  File "/home/dmytro/company/api/app/routers/user/auth.py", line 53, in login
    result = await db.execute(query)
             ^^^^^^^^^^^^^^^^^^^^^^^
  File "/home/dmytro/company/api/venv/lib/python3.12/site-packages/sqlalchemy/ext/asyncio/session.py", line 461, in execute
    result = await greenlet_spawn(
             ^^^^^^^^^^^^^^^^^^^^^
  File "/home/dmytro/company/api/venv/lib/python3.12/site-packages/sqlalchemy/util/_concurrency_py3k.py", line 201, in greenlet_spawn
    result = context.throw(*sys.exc_info())
             ^^^^^^^^^^^^^^^^^^^^^^^^^^^^^^
  File "/home/dmytro/company/api/venv/lib/python3.12/site-packages/sqlalchemy/orm/session.py", line 2351, in execute
    return self._execute_internal(
           ^^^^^^^^^^^^^^^^^^^^^^^
  File "/home/dmytro/company/api/venv/lib/python3.12/site-packages/sqlalchemy/orm/session.py", line 2236, in _execute_internal
    result: Result[Any] = compile_state_cls.orm_execute_statement(
                          ^^^^^^^^^^^^^^^^^^^^^^^^^^^^^^^^^^^^^^^^
  File "/home/dmytro/company/api/venv/lib/python3.12/site-packages/sqlalchemy/orm/context.py", line 293, in orm_execute_statement
    result = conn.execute(
             ^^^^^^^^^^^^^
  File "/home/dmytro/company/api/venv/lib/python3.12/site-packages/sqlalchemy/engine/base.py", line 1418, in execute
    return meth(
           ^^^^^
  File "/home/dmytro/company/api/venv/lib/python3.12/site-packages/sqlalchemy/sql/elements.py", line 515, in _execute_on_connection
    return connection._execute_clauseelement(
           ^^^^^^^^^^^^^^^^^^^^^^^^^^^^^^^^^^
  File "/home/dmytro/company/api/venv/lib/python3.12/site-packages/sqlalchemy/engine/base.py", line 1640, in _execute_clauseelement
    ret = self._execute_context(
          ^^^^^^^^^^^^^^^^^^^^^^
  File "/home/dmytro/company/api/venv/lib/python3.12/site-packages/sqlalchemy/engine/base.py", line 1846, in _execute_context
    return self._exec_single_context(
           ^^^^^^^^^^^^^^^^^^^^^^^^^^
  File "/home/dmytro/company/api/venv/lib/python3.12/site-packages/sqlalchemy/engine/base.py", line 1986, in _exec_single_context
    self._handle_dbapi_exception(
  File "/home/dmytro/company/api/venv/lib/python3.12/site-packages/sqlalchemy/engine/base.py", line 2353, in _handle_dbapi_exception
    raise sqlalchemy_exception.with_traceback(exc_info[2]) from e
  File "/home/dmytro/company/api/venv/lib/python3.12/site-packages/sqlalchemy/engine/base.py", line 1967, in _exec_single_context
    self.dialect.do_execute(
  File "/home/dmytro/company/api/venv/lib/python3.12/site-packages/sqlalchemy/engine/default.py", line 924, in do_execute
    cursor.execute(statement, parameters)
  File "/home/dmytro/company/api/venv/lib/python3.12/site-packages/sqlalchemy/dialects/postgresql/asyncpg.py", line 572, in execute
    self._adapt_connection.await_(
  File "/home/dmytro/company/api/venv/lib/python3.12/site-packages/sqlalchemy/util/_concurrency_py3k.py", line 132, in await_only
    return current.parent.switch(awaitable)  # type: ignore[no-any-return,attr-defined] # noqa: E501
           ^^^^^^^^^^^^^^^^^^^^^^^^^^^^^^^^
  File "/home/dmytro/company/api/venv/lib/python3.12/site-packages/sqlalchemy/util/_concurrency_py3k.py", line 196, in greenlet_spawn
    value = await result
            ^^^^^^^^^^^^
  File "/home/dmytro/company/api/venv/lib/python3.12/site-packages/sqlalchemy/dialects/postgresql/asyncpg.py", line 550, in _prepare_and_execute
    self._handle_exception(error)
  File "/home/dmytro/company/api/venv/lib/python3.12/site-packages/sqlalchemy/dialects/postgresql/asyncpg.py", line 501, in _handle_exception
    self._adapt_connection._handle_exception(error)
  File "/home/dmytro/company/api/venv/lib/python3.12/site-packages/sqlalchemy/dialects/postgresql/asyncpg.py", line 784, in _handle_exception
    raise translated_error from error
sqlalchemy.exc.ProgrammingError: (sqlalchemy.dialects.postgresql.asyncpg.ProgrammingError) <class 'asyncpg.exceptions.InsufficientPrivilegeError'>: permission denied for table users
[SQL: SELECT users.id, users.email, users.user_name, users.password, users.avatar, users.created_at, users.verified, users.token_verify, users.refresh_token, users.role, users.blocked, users.password_changed, users.company_id, users.active, users.description 
FROM users 
WHERE users.email = $1::VARCHAR]
[parameters: ('nevojt@gmail.com',)]
(Background on this error at: https://sqlalche.me/e/20/f405)
2024-09-22 18:34:38,021 - ERROR - An error occurred: Authentication (sqlalchemy.dialects.postgresql.asyncpg.ProgrammingError) <class 'asyncpg.exceptions.InsufficientPrivilegeError'>: permission denied for table users
[SQL: SELECT users.id, users.email, users.user_name, users.password, users.avatar, users.created_at, users.verified, users.token_verify, users.refresh_token, users.role, users.blocked, users.password_changed, users.company_id, users.active, users.description 
FROM users 
WHERE users.email = $1::VARCHAR]
[parameters: ('nevojt@gmail.com',)]
(Background on this error at: https://sqlalche.me/e/20/f405)
Traceback (most recent call last):
  File "/home/dmytro/company/api/venv/lib/python3.12/site-packages/sqlalchemy/dialects/postgresql/asyncpg.py", line 538, in _prepare_and_execute
    self._rows = deque(await prepared_stmt.fetch(*parameters))
                       ^^^^^^^^^^^^^^^^^^^^^^^^^^^^^^^^^^^^^^
  File "/home/dmytro/company/api/venv/lib/python3.12/site-packages/asyncpg/prepared_stmt.py", line 176, in fetch
    data = await self.__bind_execute(args, 0, timeout)
           ^^^^^^^^^^^^^^^^^^^^^^^^^^^^^^^^^^^^^^^^^^^
  File "/home/dmytro/company/api/venv/lib/python3.12/site-packages/asyncpg/prepared_stmt.py", line 241, in __bind_execute
    data, status, _ = await self.__do_execute(
                      ^^^^^^^^^^^^^^^^^^^^^^^^
  File "/home/dmytro/company/api/venv/lib/python3.12/site-packages/asyncpg/prepared_stmt.py", line 230, in __do_execute
    return await executor(protocol)
           ^^^^^^^^^^^^^^^^^^^^^^^^
  File "asyncpg/protocol/protocol.pyx", line 207, in bind_execute
asyncpg.exceptions.InsufficientPrivilegeError: permission denied for table users

The above exception was the direct cause of the following exception:

Traceback (most recent call last):
  File "/home/dmytro/company/api/venv/lib/python3.12/site-packages/sqlalchemy/engine/base.py", line 1967, in _exec_single_context
    self.dialect.do_execute(
  File "/home/dmytro/company/api/venv/lib/python3.12/site-packages/sqlalchemy/engine/default.py", line 924, in do_execute
    cursor.execute(statement, parameters)
  File "/home/dmytro/company/api/venv/lib/python3.12/site-packages/sqlalchemy/dialects/postgresql/asyncpg.py", line 572, in execute
    self._adapt_connection.await_(
  File "/home/dmytro/company/api/venv/lib/python3.12/site-packages/sqlalchemy/util/_concurrency_py3k.py", line 132, in await_only
    return current.parent.switch(awaitable)  # type: ignore[no-any-return,attr-defined] # noqa: E501
           ^^^^^^^^^^^^^^^^^^^^^^^^^^^^^^^^
  File "/home/dmytro/company/api/venv/lib/python3.12/site-packages/sqlalchemy/util/_concurrency_py3k.py", line 196, in greenlet_spawn
    value = await result
            ^^^^^^^^^^^^
  File "/home/dmytro/company/api/venv/lib/python3.12/site-packages/sqlalchemy/dialects/postgresql/asyncpg.py", line 550, in _prepare_and_execute
    self._handle_exception(error)
  File "/home/dmytro/company/api/venv/lib/python3.12/site-packages/sqlalchemy/dialects/postgresql/asyncpg.py", line 501, in _handle_exception
    self._adapt_connection._handle_exception(error)
  File "/home/dmytro/company/api/venv/lib/python3.12/site-packages/sqlalchemy/dialects/postgresql/asyncpg.py", line 784, in _handle_exception
    raise translated_error from error
sqlalchemy.dialects.postgresql.asyncpg.AsyncAdapt_asyncpg_dbapi.ProgrammingError: <class 'asyncpg.exceptions.InsufficientPrivilegeError'>: permission denied for table users

The above exception was the direct cause of the following exception:

Traceback (most recent call last):
  File "/home/dmytro/company/api/app/routers/user/auth.py", line 53, in login
    result = await db.execute(query)
             ^^^^^^^^^^^^^^^^^^^^^^^
  File "/home/dmytro/company/api/venv/lib/python3.12/site-packages/sqlalchemy/ext/asyncio/session.py", line 461, in execute
    result = await greenlet_spawn(
             ^^^^^^^^^^^^^^^^^^^^^
  File "/home/dmytro/company/api/venv/lib/python3.12/site-packages/sqlalchemy/util/_concurrency_py3k.py", line 201, in greenlet_spawn
    result = context.throw(*sys.exc_info())
             ^^^^^^^^^^^^^^^^^^^^^^^^^^^^^^
  File "/home/dmytro/company/api/venv/lib/python3.12/site-packages/sqlalchemy/orm/session.py", line 2351, in execute
    return self._execute_internal(
           ^^^^^^^^^^^^^^^^^^^^^^^
  File "/home/dmytro/company/api/venv/lib/python3.12/site-packages/sqlalchemy/orm/session.py", line 2236, in _execute_internal
    result: Result[Any] = compile_state_cls.orm_execute_statement(
                          ^^^^^^^^^^^^^^^^^^^^^^^^^^^^^^^^^^^^^^^^
  File "/home/dmytro/company/api/venv/lib/python3.12/site-packages/sqlalchemy/orm/context.py", line 293, in orm_execute_statement
    result = conn.execute(
             ^^^^^^^^^^^^^
  File "/home/dmytro/company/api/venv/lib/python3.12/site-packages/sqlalchemy/engine/base.py", line 1418, in execute
    return meth(
           ^^^^^
  File "/home/dmytro/company/api/venv/lib/python3.12/site-packages/sqlalchemy/sql/elements.py", line 515, in _execute_on_connection
    return connection._execute_clauseelement(
           ^^^^^^^^^^^^^^^^^^^^^^^^^^^^^^^^^^
  File "/home/dmytro/company/api/venv/lib/python3.12/site-packages/sqlalchemy/engine/base.py", line 1640, in _execute_clauseelement
    ret = self._execute_context(
          ^^^^^^^^^^^^^^^^^^^^^^
  File "/home/dmytro/company/api/venv/lib/python3.12/site-packages/sqlalchemy/engine/base.py", line 1846, in _execute_context
    return self._exec_single_context(
           ^^^^^^^^^^^^^^^^^^^^^^^^^^
  File "/home/dmytro/company/api/venv/lib/python3.12/site-packages/sqlalchemy/engine/base.py", line 1986, in _exec_single_context
    self._handle_dbapi_exception(
  File "/home/dmytro/company/api/venv/lib/python3.12/site-packages/sqlalchemy/engine/base.py", line 2353, in _handle_dbapi_exception
    raise sqlalchemy_exception.with_traceback(exc_info[2]) from e
  File "/home/dmytro/company/api/venv/lib/python3.12/site-packages/sqlalchemy/engine/base.py", line 1967, in _exec_single_context
    self.dialect.do_execute(
  File "/home/dmytro/company/api/venv/lib/python3.12/site-packages/sqlalchemy/engine/default.py", line 924, in do_execute
    cursor.execute(statement, parameters)
  File "/home/dmytro/company/api/venv/lib/python3.12/site-packages/sqlalchemy/dialects/postgresql/asyncpg.py", line 572, in execute
    self._adapt_connection.await_(
  File "/home/dmytro/company/api/venv/lib/python3.12/site-packages/sqlalchemy/util/_concurrency_py3k.py", line 132, in await_only
    return current.parent.switch(awaitable)  # type: ignore[no-any-return,attr-defined] # noqa: E501
           ^^^^^^^^^^^^^^^^^^^^^^^^^^^^^^^^
  File "/home/dmytro/company/api/venv/lib/python3.12/site-packages/sqlalchemy/util/_concurrency_py3k.py", line 196, in greenlet_spawn
    value = await result
            ^^^^^^^^^^^^
  File "/home/dmytro/company/api/venv/lib/python3.12/site-packages/sqlalchemy/dialects/postgresql/asyncpg.py", line 550, in _prepare_and_execute
    self._handle_exception(error)
  File "/home/dmytro/company/api/venv/lib/python3.12/site-packages/sqlalchemy/dialects/postgresql/asyncpg.py", line 501, in _handle_exception
    self._adapt_connection._handle_exception(error)
  File "/home/dmytro/company/api/venv/lib/python3.12/site-packages/sqlalchemy/dialects/postgresql/asyncpg.py", line 784, in _handle_exception
    raise translated_error from error
sqlalchemy.exc.ProgrammingError: (sqlalchemy.dialects.postgresql.asyncpg.ProgrammingError) <class 'asyncpg.exceptions.InsufficientPrivilegeError'>: permission denied for table users
[SQL: SELECT users.id, users.email, users.user_name, users.password, users.avatar, users.created_at, users.verified, users.token_verify, users.refresh_token, users.role, users.blocked, users.password_changed, users.company_id, users.active, users.description 
FROM users 
WHERE users.email = $1::VARCHAR]
[parameters: ('nevojt@gmail.com',)]
(Background on this error at: https://sqlalche.me/e/20/f405)
2024-09-22 18:38:02,619 - ERROR - An error occurred: Authentication (sqlalchemy.dialects.postgresql.asyncpg.ProgrammingError) <class 'asyncpg.exceptions.InsufficientPrivilegeError'>: permission denied for table users
[SQL: SELECT users.id, users.email, users.user_name, users.password, users.avatar, users.created_at, users.verified, users.token_verify, users.refresh_token, users.role, users.blocked, users.password_changed, users.company_id, users.active, users.description 
FROM users 
WHERE users.email = $1::VARCHAR]
[parameters: ('nevojt@gmail.com',)]
(Background on this error at: https://sqlalche.me/e/20/f405)
Traceback (most recent call last):
  File "/home/dmytro/company/api/venv/lib/python3.12/site-packages/sqlalchemy/dialects/postgresql/asyncpg.py", line 538, in _prepare_and_execute
    self._rows = deque(await prepared_stmt.fetch(*parameters))
                       ^^^^^^^^^^^^^^^^^^^^^^^^^^^^^^^^^^^^^^
  File "/home/dmytro/company/api/venv/lib/python3.12/site-packages/asyncpg/prepared_stmt.py", line 176, in fetch
    data = await self.__bind_execute(args, 0, timeout)
           ^^^^^^^^^^^^^^^^^^^^^^^^^^^^^^^^^^^^^^^^^^^
  File "/home/dmytro/company/api/venv/lib/python3.12/site-packages/asyncpg/prepared_stmt.py", line 241, in __bind_execute
    data, status, _ = await self.__do_execute(
                      ^^^^^^^^^^^^^^^^^^^^^^^^
  File "/home/dmytro/company/api/venv/lib/python3.12/site-packages/asyncpg/prepared_stmt.py", line 230, in __do_execute
    return await executor(protocol)
           ^^^^^^^^^^^^^^^^^^^^^^^^
  File "asyncpg/protocol/protocol.pyx", line 207, in bind_execute
asyncpg.exceptions.InsufficientPrivilegeError: permission denied for table users

The above exception was the direct cause of the following exception:

Traceback (most recent call last):
  File "/home/dmytro/company/api/venv/lib/python3.12/site-packages/sqlalchemy/engine/base.py", line 1967, in _exec_single_context
    self.dialect.do_execute(
  File "/home/dmytro/company/api/venv/lib/python3.12/site-packages/sqlalchemy/engine/default.py", line 924, in do_execute
    cursor.execute(statement, parameters)
  File "/home/dmytro/company/api/venv/lib/python3.12/site-packages/sqlalchemy/dialects/postgresql/asyncpg.py", line 572, in execute
    self._adapt_connection.await_(
  File "/home/dmytro/company/api/venv/lib/python3.12/site-packages/sqlalchemy/util/_concurrency_py3k.py", line 132, in await_only
    return current.parent.switch(awaitable)  # type: ignore[no-any-return,attr-defined] # noqa: E501
           ^^^^^^^^^^^^^^^^^^^^^^^^^^^^^^^^
  File "/home/dmytro/company/api/venv/lib/python3.12/site-packages/sqlalchemy/util/_concurrency_py3k.py", line 196, in greenlet_spawn
    value = await result
            ^^^^^^^^^^^^
  File "/home/dmytro/company/api/venv/lib/python3.12/site-packages/sqlalchemy/dialects/postgresql/asyncpg.py", line 550, in _prepare_and_execute
    self._handle_exception(error)
  File "/home/dmytro/company/api/venv/lib/python3.12/site-packages/sqlalchemy/dialects/postgresql/asyncpg.py", line 501, in _handle_exception
    self._adapt_connection._handle_exception(error)
  File "/home/dmytro/company/api/venv/lib/python3.12/site-packages/sqlalchemy/dialects/postgresql/asyncpg.py", line 784, in _handle_exception
    raise translated_error from error
sqlalchemy.dialects.postgresql.asyncpg.AsyncAdapt_asyncpg_dbapi.ProgrammingError: <class 'asyncpg.exceptions.InsufficientPrivilegeError'>: permission denied for table users

The above exception was the direct cause of the following exception:

Traceback (most recent call last):
  File "/home/dmytro/company/api/app/routers/user/auth.py", line 53, in login
    result = await db.execute(query)
             ^^^^^^^^^^^^^^^^^^^^^^^
  File "/home/dmytro/company/api/venv/lib/python3.12/site-packages/sqlalchemy/ext/asyncio/session.py", line 461, in execute
    result = await greenlet_spawn(
             ^^^^^^^^^^^^^^^^^^^^^
  File "/home/dmytro/company/api/venv/lib/python3.12/site-packages/sqlalchemy/util/_concurrency_py3k.py", line 201, in greenlet_spawn
    result = context.throw(*sys.exc_info())
             ^^^^^^^^^^^^^^^^^^^^^^^^^^^^^^
  File "/home/dmytro/company/api/venv/lib/python3.12/site-packages/sqlalchemy/orm/session.py", line 2351, in execute
    return self._execute_internal(
           ^^^^^^^^^^^^^^^^^^^^^^^
  File "/home/dmytro/company/api/venv/lib/python3.12/site-packages/sqlalchemy/orm/session.py", line 2236, in _execute_internal
    result: Result[Any] = compile_state_cls.orm_execute_statement(
                          ^^^^^^^^^^^^^^^^^^^^^^^^^^^^^^^^^^^^^^^^
  File "/home/dmytro/company/api/venv/lib/python3.12/site-packages/sqlalchemy/orm/context.py", line 293, in orm_execute_statement
    result = conn.execute(
             ^^^^^^^^^^^^^
  File "/home/dmytro/company/api/venv/lib/python3.12/site-packages/sqlalchemy/engine/base.py", line 1418, in execute
    return meth(
           ^^^^^
  File "/home/dmytro/company/api/venv/lib/python3.12/site-packages/sqlalchemy/sql/elements.py", line 515, in _execute_on_connection
    return connection._execute_clauseelement(
           ^^^^^^^^^^^^^^^^^^^^^^^^^^^^^^^^^^
  File "/home/dmytro/company/api/venv/lib/python3.12/site-packages/sqlalchemy/engine/base.py", line 1640, in _execute_clauseelement
    ret = self._execute_context(
          ^^^^^^^^^^^^^^^^^^^^^^
  File "/home/dmytro/company/api/venv/lib/python3.12/site-packages/sqlalchemy/engine/base.py", line 1846, in _execute_context
    return self._exec_single_context(
           ^^^^^^^^^^^^^^^^^^^^^^^^^^
  File "/home/dmytro/company/api/venv/lib/python3.12/site-packages/sqlalchemy/engine/base.py", line 1986, in _exec_single_context
    self._handle_dbapi_exception(
  File "/home/dmytro/company/api/venv/lib/python3.12/site-packages/sqlalchemy/engine/base.py", line 2353, in _handle_dbapi_exception
    raise sqlalchemy_exception.with_traceback(exc_info[2]) from e
  File "/home/dmytro/company/api/venv/lib/python3.12/site-packages/sqlalchemy/engine/base.py", line 1967, in _exec_single_context
    self.dialect.do_execute(
  File "/home/dmytro/company/api/venv/lib/python3.12/site-packages/sqlalchemy/engine/default.py", line 924, in do_execute
    cursor.execute(statement, parameters)
  File "/home/dmytro/company/api/venv/lib/python3.12/site-packages/sqlalchemy/dialects/postgresql/asyncpg.py", line 572, in execute
    self._adapt_connection.await_(
  File "/home/dmytro/company/api/venv/lib/python3.12/site-packages/sqlalchemy/util/_concurrency_py3k.py", line 132, in await_only
    return current.parent.switch(awaitable)  # type: ignore[no-any-return,attr-defined] # noqa: E501
           ^^^^^^^^^^^^^^^^^^^^^^^^^^^^^^^^
  File "/home/dmytro/company/api/venv/lib/python3.12/site-packages/sqlalchemy/util/_concurrency_py3k.py", line 196, in greenlet_spawn
    value = await result
            ^^^^^^^^^^^^
  File "/home/dmytro/company/api/venv/lib/python3.12/site-packages/sqlalchemy/dialects/postgresql/asyncpg.py", line 550, in _prepare_and_execute
    self._handle_exception(error)
  File "/home/dmytro/company/api/venv/lib/python3.12/site-packages/sqlalchemy/dialects/postgresql/asyncpg.py", line 501, in _handle_exception
    self._adapt_connection._handle_exception(error)
  File "/home/dmytro/company/api/venv/lib/python3.12/site-packages/sqlalchemy/dialects/postgresql/asyncpg.py", line 784, in _handle_exception
    raise translated_error from error
sqlalchemy.exc.ProgrammingError: (sqlalchemy.dialects.postgresql.asyncpg.ProgrammingError) <class 'asyncpg.exceptions.InsufficientPrivilegeError'>: permission denied for table users
[SQL: SELECT users.id, users.email, users.user_name, users.password, users.avatar, users.created_at, users.verified, users.token_verify, users.refresh_token, users.role, users.blocked, users.password_changed, users.company_id, users.active, users.description 
FROM users 
WHERE users.email = $1::VARCHAR]
[parameters: ('nevojt@gmail.com',)]
(Background on this error at: https://sqlalche.me/e/20/f405)
2024-09-22 18:39:30,155 - ERROR - An error occurred: Authentication (sqlalchemy.dialects.postgresql.asyncpg.ProgrammingError) <class 'asyncpg.exceptions.InsufficientPrivilegeError'>: permission denied for table users
[SQL: SELECT users.id, users.email, users.user_name, users.password, users.avatar, users.created_at, users.verified, users.token_verify, users.refresh_token, users.role, users.blocked, users.password_changed, users.company_id, users.active, users.description 
FROM users 
WHERE users.email = $1::VARCHAR]
[parameters: ('nevojt@gmail.com',)]
(Background on this error at: https://sqlalche.me/e/20/f405)
Traceback (most recent call last):
  File "/home/dmytro/company/api/venv/lib/python3.12/site-packages/sqlalchemy/dialects/postgresql/asyncpg.py", line 538, in _prepare_and_execute
    self._rows = deque(await prepared_stmt.fetch(*parameters))
                       ^^^^^^^^^^^^^^^^^^^^^^^^^^^^^^^^^^^^^^
  File "/home/dmytro/company/api/venv/lib/python3.12/site-packages/asyncpg/prepared_stmt.py", line 176, in fetch
    data = await self.__bind_execute(args, 0, timeout)
           ^^^^^^^^^^^^^^^^^^^^^^^^^^^^^^^^^^^^^^^^^^^
  File "/home/dmytro/company/api/venv/lib/python3.12/site-packages/asyncpg/prepared_stmt.py", line 241, in __bind_execute
    data, status, _ = await self.__do_execute(
                      ^^^^^^^^^^^^^^^^^^^^^^^^
  File "/home/dmytro/company/api/venv/lib/python3.12/site-packages/asyncpg/prepared_stmt.py", line 230, in __do_execute
    return await executor(protocol)
           ^^^^^^^^^^^^^^^^^^^^^^^^
  File "asyncpg/protocol/protocol.pyx", line 207, in bind_execute
asyncpg.exceptions.InsufficientPrivilegeError: permission denied for table users

The above exception was the direct cause of the following exception:

Traceback (most recent call last):
  File "/home/dmytro/company/api/venv/lib/python3.12/site-packages/sqlalchemy/engine/base.py", line 1967, in _exec_single_context
    self.dialect.do_execute(
  File "/home/dmytro/company/api/venv/lib/python3.12/site-packages/sqlalchemy/engine/default.py", line 924, in do_execute
    cursor.execute(statement, parameters)
  File "/home/dmytro/company/api/venv/lib/python3.12/site-packages/sqlalchemy/dialects/postgresql/asyncpg.py", line 572, in execute
    self._adapt_connection.await_(
  File "/home/dmytro/company/api/venv/lib/python3.12/site-packages/sqlalchemy/util/_concurrency_py3k.py", line 132, in await_only
    return current.parent.switch(awaitable)  # type: ignore[no-any-return,attr-defined] # noqa: E501
           ^^^^^^^^^^^^^^^^^^^^^^^^^^^^^^^^
  File "/home/dmytro/company/api/venv/lib/python3.12/site-packages/sqlalchemy/util/_concurrency_py3k.py", line 196, in greenlet_spawn
    value = await result
            ^^^^^^^^^^^^
  File "/home/dmytro/company/api/venv/lib/python3.12/site-packages/sqlalchemy/dialects/postgresql/asyncpg.py", line 550, in _prepare_and_execute
    self._handle_exception(error)
  File "/home/dmytro/company/api/venv/lib/python3.12/site-packages/sqlalchemy/dialects/postgresql/asyncpg.py", line 501, in _handle_exception
    self._adapt_connection._handle_exception(error)
  File "/home/dmytro/company/api/venv/lib/python3.12/site-packages/sqlalchemy/dialects/postgresql/asyncpg.py", line 784, in _handle_exception
    raise translated_error from error
sqlalchemy.dialects.postgresql.asyncpg.AsyncAdapt_asyncpg_dbapi.ProgrammingError: <class 'asyncpg.exceptions.InsufficientPrivilegeError'>: permission denied for table users

The above exception was the direct cause of the following exception:

Traceback (most recent call last):
  File "/home/dmytro/company/api/app/routers/user/auth.py", line 53, in login
    result = await db.execute(query)
             ^^^^^^^^^^^^^^^^^^^^^^^
  File "/home/dmytro/company/api/venv/lib/python3.12/site-packages/sqlalchemy/ext/asyncio/session.py", line 461, in execute
    result = await greenlet_spawn(
             ^^^^^^^^^^^^^^^^^^^^^
  File "/home/dmytro/company/api/venv/lib/python3.12/site-packages/sqlalchemy/util/_concurrency_py3k.py", line 201, in greenlet_spawn
    result = context.throw(*sys.exc_info())
             ^^^^^^^^^^^^^^^^^^^^^^^^^^^^^^
  File "/home/dmytro/company/api/venv/lib/python3.12/site-packages/sqlalchemy/orm/session.py", line 2351, in execute
    return self._execute_internal(
           ^^^^^^^^^^^^^^^^^^^^^^^
  File "/home/dmytro/company/api/venv/lib/python3.12/site-packages/sqlalchemy/orm/session.py", line 2236, in _execute_internal
    result: Result[Any] = compile_state_cls.orm_execute_statement(
                          ^^^^^^^^^^^^^^^^^^^^^^^^^^^^^^^^^^^^^^^^
  File "/home/dmytro/company/api/venv/lib/python3.12/site-packages/sqlalchemy/orm/context.py", line 293, in orm_execute_statement
    result = conn.execute(
             ^^^^^^^^^^^^^
  File "/home/dmytro/company/api/venv/lib/python3.12/site-packages/sqlalchemy/engine/base.py", line 1418, in execute
    return meth(
           ^^^^^
  File "/home/dmytro/company/api/venv/lib/python3.12/site-packages/sqlalchemy/sql/elements.py", line 515, in _execute_on_connection
    return connection._execute_clauseelement(
           ^^^^^^^^^^^^^^^^^^^^^^^^^^^^^^^^^^
  File "/home/dmytro/company/api/venv/lib/python3.12/site-packages/sqlalchemy/engine/base.py", line 1640, in _execute_clauseelement
    ret = self._execute_context(
          ^^^^^^^^^^^^^^^^^^^^^^
  File "/home/dmytro/company/api/venv/lib/python3.12/site-packages/sqlalchemy/engine/base.py", line 1846, in _execute_context
    return self._exec_single_context(
           ^^^^^^^^^^^^^^^^^^^^^^^^^^
  File "/home/dmytro/company/api/venv/lib/python3.12/site-packages/sqlalchemy/engine/base.py", line 1986, in _exec_single_context
    self._handle_dbapi_exception(
  File "/home/dmytro/company/api/venv/lib/python3.12/site-packages/sqlalchemy/engine/base.py", line 2353, in _handle_dbapi_exception
    raise sqlalchemy_exception.with_traceback(exc_info[2]) from e
  File "/home/dmytro/company/api/venv/lib/python3.12/site-packages/sqlalchemy/engine/base.py", line 1967, in _exec_single_context
    self.dialect.do_execute(
  File "/home/dmytro/company/api/venv/lib/python3.12/site-packages/sqlalchemy/engine/default.py", line 924, in do_execute
    cursor.execute(statement, parameters)
  File "/home/dmytro/company/api/venv/lib/python3.12/site-packages/sqlalchemy/dialects/postgresql/asyncpg.py", line 572, in execute
    self._adapt_connection.await_(
  File "/home/dmytro/company/api/venv/lib/python3.12/site-packages/sqlalchemy/util/_concurrency_py3k.py", line 132, in await_only
    return current.parent.switch(awaitable)  # type: ignore[no-any-return,attr-defined] # noqa: E501
           ^^^^^^^^^^^^^^^^^^^^^^^^^^^^^^^^
  File "/home/dmytro/company/api/venv/lib/python3.12/site-packages/sqlalchemy/util/_concurrency_py3k.py", line 196, in greenlet_spawn
    value = await result
            ^^^^^^^^^^^^
  File "/home/dmytro/company/api/venv/lib/python3.12/site-packages/sqlalchemy/dialects/postgresql/asyncpg.py", line 550, in _prepare_and_execute
    self._handle_exception(error)
  File "/home/dmytro/company/api/venv/lib/python3.12/site-packages/sqlalchemy/dialects/postgresql/asyncpg.py", line 501, in _handle_exception
    self._adapt_connection._handle_exception(error)
  File "/home/dmytro/company/api/venv/lib/python3.12/site-packages/sqlalchemy/dialects/postgresql/asyncpg.py", line 784, in _handle_exception
    raise translated_error from error
sqlalchemy.exc.ProgrammingError: (sqlalchemy.dialects.postgresql.asyncpg.ProgrammingError) <class 'asyncpg.exceptions.InsufficientPrivilegeError'>: permission denied for table users
[SQL: SELECT users.id, users.email, users.user_name, users.password, users.avatar, users.created_at, users.verified, users.token_verify, users.refresh_token, users.role, users.blocked, users.password_changed, users.company_id, users.active, users.description 
FROM users 
WHERE users.email = $1::VARCHAR]
[parameters: ('nevojt@gmail.com',)]
(Background on this error at: https://sqlalche.me/e/20/f405)
2024-09-22 18:40:45,202 - ERROR - An error occurred: Authentication (sqlalchemy.dialects.postgresql.asyncpg.ProgrammingError) <class 'asyncpg.exceptions.InsufficientPrivilegeError'>: permission denied for table users
[SQL: SELECT users.id, users.email, users.user_name, users.password, users.avatar, users.created_at, users.verified, users.token_verify, users.refresh_token, users.role, users.blocked, users.password_changed, users.company_id, users.active, users.description 
FROM users 
WHERE users.email = $1::VARCHAR]
[parameters: ('nevojt@gmail.com',)]
(Background on this error at: https://sqlalche.me/e/20/f405)
Traceback (most recent call last):
  File "/home/dmytro/company/api/venv/lib/python3.12/site-packages/sqlalchemy/dialects/postgresql/asyncpg.py", line 538, in _prepare_and_execute
    self._rows = deque(await prepared_stmt.fetch(*parameters))
                       ^^^^^^^^^^^^^^^^^^^^^^^^^^^^^^^^^^^^^^
  File "/home/dmytro/company/api/venv/lib/python3.12/site-packages/asyncpg/prepared_stmt.py", line 176, in fetch
    data = await self.__bind_execute(args, 0, timeout)
           ^^^^^^^^^^^^^^^^^^^^^^^^^^^^^^^^^^^^^^^^^^^
  File "/home/dmytro/company/api/venv/lib/python3.12/site-packages/asyncpg/prepared_stmt.py", line 241, in __bind_execute
    data, status, _ = await self.__do_execute(
                      ^^^^^^^^^^^^^^^^^^^^^^^^
  File "/home/dmytro/company/api/venv/lib/python3.12/site-packages/asyncpg/prepared_stmt.py", line 230, in __do_execute
    return await executor(protocol)
           ^^^^^^^^^^^^^^^^^^^^^^^^
  File "asyncpg/protocol/protocol.pyx", line 207, in bind_execute
asyncpg.exceptions.InsufficientPrivilegeError: permission denied for table users

The above exception was the direct cause of the following exception:

Traceback (most recent call last):
  File "/home/dmytro/company/api/venv/lib/python3.12/site-packages/sqlalchemy/engine/base.py", line 1967, in _exec_single_context
    self.dialect.do_execute(
  File "/home/dmytro/company/api/venv/lib/python3.12/site-packages/sqlalchemy/engine/default.py", line 924, in do_execute
    cursor.execute(statement, parameters)
  File "/home/dmytro/company/api/venv/lib/python3.12/site-packages/sqlalchemy/dialects/postgresql/asyncpg.py", line 572, in execute
    self._adapt_connection.await_(
  File "/home/dmytro/company/api/venv/lib/python3.12/site-packages/sqlalchemy/util/_concurrency_py3k.py", line 132, in await_only
    return current.parent.switch(awaitable)  # type: ignore[no-any-return,attr-defined] # noqa: E501
           ^^^^^^^^^^^^^^^^^^^^^^^^^^^^^^^^
  File "/home/dmytro/company/api/venv/lib/python3.12/site-packages/sqlalchemy/util/_concurrency_py3k.py", line 196, in greenlet_spawn
    value = await result
            ^^^^^^^^^^^^
  File "/home/dmytro/company/api/venv/lib/python3.12/site-packages/sqlalchemy/dialects/postgresql/asyncpg.py", line 550, in _prepare_and_execute
    self._handle_exception(error)
  File "/home/dmytro/company/api/venv/lib/python3.12/site-packages/sqlalchemy/dialects/postgresql/asyncpg.py", line 501, in _handle_exception
    self._adapt_connection._handle_exception(error)
  File "/home/dmytro/company/api/venv/lib/python3.12/site-packages/sqlalchemy/dialects/postgresql/asyncpg.py", line 784, in _handle_exception
    raise translated_error from error
sqlalchemy.dialects.postgresql.asyncpg.AsyncAdapt_asyncpg_dbapi.ProgrammingError: <class 'asyncpg.exceptions.InsufficientPrivilegeError'>: permission denied for table users

The above exception was the direct cause of the following exception:

Traceback (most recent call last):
  File "/home/dmytro/company/api/app/routers/user/auth.py", line 53, in login
    result = await db.execute(query)
             ^^^^^^^^^^^^^^^^^^^^^^^
  File "/home/dmytro/company/api/venv/lib/python3.12/site-packages/sqlalchemy/ext/asyncio/session.py", line 461, in execute
    result = await greenlet_spawn(
             ^^^^^^^^^^^^^^^^^^^^^
  File "/home/dmytro/company/api/venv/lib/python3.12/site-packages/sqlalchemy/util/_concurrency_py3k.py", line 201, in greenlet_spawn
    result = context.throw(*sys.exc_info())
             ^^^^^^^^^^^^^^^^^^^^^^^^^^^^^^
  File "/home/dmytro/company/api/venv/lib/python3.12/site-packages/sqlalchemy/orm/session.py", line 2351, in execute
    return self._execute_internal(
           ^^^^^^^^^^^^^^^^^^^^^^^
  File "/home/dmytro/company/api/venv/lib/python3.12/site-packages/sqlalchemy/orm/session.py", line 2236, in _execute_internal
    result: Result[Any] = compile_state_cls.orm_execute_statement(
                          ^^^^^^^^^^^^^^^^^^^^^^^^^^^^^^^^^^^^^^^^
  File "/home/dmytro/company/api/venv/lib/python3.12/site-packages/sqlalchemy/orm/context.py", line 293, in orm_execute_statement
    result = conn.execute(
             ^^^^^^^^^^^^^
  File "/home/dmytro/company/api/venv/lib/python3.12/site-packages/sqlalchemy/engine/base.py", line 1418, in execute
    return meth(
           ^^^^^
  File "/home/dmytro/company/api/venv/lib/python3.12/site-packages/sqlalchemy/sql/elements.py", line 515, in _execute_on_connection
    return connection._execute_clauseelement(
           ^^^^^^^^^^^^^^^^^^^^^^^^^^^^^^^^^^
  File "/home/dmytro/company/api/venv/lib/python3.12/site-packages/sqlalchemy/engine/base.py", line 1640, in _execute_clauseelement
    ret = self._execute_context(
          ^^^^^^^^^^^^^^^^^^^^^^
  File "/home/dmytro/company/api/venv/lib/python3.12/site-packages/sqlalchemy/engine/base.py", line 1846, in _execute_context
    return self._exec_single_context(
           ^^^^^^^^^^^^^^^^^^^^^^^^^^
  File "/home/dmytro/company/api/venv/lib/python3.12/site-packages/sqlalchemy/engine/base.py", line 1986, in _exec_single_context
    self._handle_dbapi_exception(
  File "/home/dmytro/company/api/venv/lib/python3.12/site-packages/sqlalchemy/engine/base.py", line 2353, in _handle_dbapi_exception
    raise sqlalchemy_exception.with_traceback(exc_info[2]) from e
  File "/home/dmytro/company/api/venv/lib/python3.12/site-packages/sqlalchemy/engine/base.py", line 1967, in _exec_single_context
    self.dialect.do_execute(
  File "/home/dmytro/company/api/venv/lib/python3.12/site-packages/sqlalchemy/engine/default.py", line 924, in do_execute
    cursor.execute(statement, parameters)
  File "/home/dmytro/company/api/venv/lib/python3.12/site-packages/sqlalchemy/dialects/postgresql/asyncpg.py", line 572, in execute
    self._adapt_connection.await_(
  File "/home/dmytro/company/api/venv/lib/python3.12/site-packages/sqlalchemy/util/_concurrency_py3k.py", line 132, in await_only
    return current.parent.switch(awaitable)  # type: ignore[no-any-return,attr-defined] # noqa: E501
           ^^^^^^^^^^^^^^^^^^^^^^^^^^^^^^^^
  File "/home/dmytro/company/api/venv/lib/python3.12/site-packages/sqlalchemy/util/_concurrency_py3k.py", line 196, in greenlet_spawn
    value = await result
            ^^^^^^^^^^^^
  File "/home/dmytro/company/api/venv/lib/python3.12/site-packages/sqlalchemy/dialects/postgresql/asyncpg.py", line 550, in _prepare_and_execute
    self._handle_exception(error)
  File "/home/dmytro/company/api/venv/lib/python3.12/site-packages/sqlalchemy/dialects/postgresql/asyncpg.py", line 501, in _handle_exception
    self._adapt_connection._handle_exception(error)
  File "/home/dmytro/company/api/venv/lib/python3.12/site-packages/sqlalchemy/dialects/postgresql/asyncpg.py", line 784, in _handle_exception
    raise translated_error from error
sqlalchemy.exc.ProgrammingError: (sqlalchemy.dialects.postgresql.asyncpg.ProgrammingError) <class 'asyncpg.exceptions.InsufficientPrivilegeError'>: permission denied for table users
[SQL: SELECT users.id, users.email, users.user_name, users.password, users.avatar, users.created_at, users.verified, users.token_verify, users.refresh_token, users.role, users.blocked, users.password_changed, users.company_id, users.active, users.description 
FROM users 
WHERE users.email = $1::VARCHAR]
[parameters: ('nevojt@gmail.com',)]
(Background on this error at: https://sqlalche.me/e/20/f405)
2024-09-22 18:58:40,018 - ERROR - An error occurred: Authentication (sqlalchemy.dialects.postgresql.asyncpg.ProgrammingError) <class 'asyncpg.exceptions.InsufficientPrivilegeError'>: permission denied for table users
[SQL: SELECT users.id, users.email, users.user_name, users.password, users.avatar, users.created_at, users.verified, users.token_verify, users.refresh_token, users.role, users.blocked, users.password_changed, users.company_id, users.active, users.description 
FROM users 
WHERE users.email = $1::VARCHAR]
[parameters: ('nevojt@gmail.com',)]
(Background on this error at: https://sqlalche.me/e/20/f405)
Traceback (most recent call last):
  File "/home/dmytro/company/api/venv/lib/python3.12/site-packages/sqlalchemy/dialects/postgresql/asyncpg.py", line 538, in _prepare_and_execute
    self._rows = deque(await prepared_stmt.fetch(*parameters))
                       ^^^^^^^^^^^^^^^^^^^^^^^^^^^^^^^^^^^^^^
  File "/home/dmytro/company/api/venv/lib/python3.12/site-packages/asyncpg/prepared_stmt.py", line 176, in fetch
    data = await self.__bind_execute(args, 0, timeout)
           ^^^^^^^^^^^^^^^^^^^^^^^^^^^^^^^^^^^^^^^^^^^
  File "/home/dmytro/company/api/venv/lib/python3.12/site-packages/asyncpg/prepared_stmt.py", line 241, in __bind_execute
    data, status, _ = await self.__do_execute(
                      ^^^^^^^^^^^^^^^^^^^^^^^^
  File "/home/dmytro/company/api/venv/lib/python3.12/site-packages/asyncpg/prepared_stmt.py", line 230, in __do_execute
    return await executor(protocol)
           ^^^^^^^^^^^^^^^^^^^^^^^^
  File "asyncpg/protocol/protocol.pyx", line 207, in bind_execute
asyncpg.exceptions.InsufficientPrivilegeError: permission denied for table users

The above exception was the direct cause of the following exception:

Traceback (most recent call last):
  File "/home/dmytro/company/api/venv/lib/python3.12/site-packages/sqlalchemy/engine/base.py", line 1967, in _exec_single_context
    self.dialect.do_execute(
  File "/home/dmytro/company/api/venv/lib/python3.12/site-packages/sqlalchemy/engine/default.py", line 924, in do_execute
    cursor.execute(statement, parameters)
  File "/home/dmytro/company/api/venv/lib/python3.12/site-packages/sqlalchemy/dialects/postgresql/asyncpg.py", line 572, in execute
    self._adapt_connection.await_(
  File "/home/dmytro/company/api/venv/lib/python3.12/site-packages/sqlalchemy/util/_concurrency_py3k.py", line 132, in await_only
    return current.parent.switch(awaitable)  # type: ignore[no-any-return,attr-defined] # noqa: E501
           ^^^^^^^^^^^^^^^^^^^^^^^^^^^^^^^^
  File "/home/dmytro/company/api/venv/lib/python3.12/site-packages/sqlalchemy/util/_concurrency_py3k.py", line 196, in greenlet_spawn
    value = await result
            ^^^^^^^^^^^^
  File "/home/dmytro/company/api/venv/lib/python3.12/site-packages/sqlalchemy/dialects/postgresql/asyncpg.py", line 550, in _prepare_and_execute
    self._handle_exception(error)
  File "/home/dmytro/company/api/venv/lib/python3.12/site-packages/sqlalchemy/dialects/postgresql/asyncpg.py", line 501, in _handle_exception
    self._adapt_connection._handle_exception(error)
  File "/home/dmytro/company/api/venv/lib/python3.12/site-packages/sqlalchemy/dialects/postgresql/asyncpg.py", line 784, in _handle_exception
    raise translated_error from error
sqlalchemy.dialects.postgresql.asyncpg.AsyncAdapt_asyncpg_dbapi.ProgrammingError: <class 'asyncpg.exceptions.InsufficientPrivilegeError'>: permission denied for table users

The above exception was the direct cause of the following exception:

Traceback (most recent call last):
  File "/home/dmytro/company/api/app/routers/user/auth.py", line 53, in login
    result = await db.execute(query)
             ^^^^^^^^^^^^^^^^^^^^^^^
  File "/home/dmytro/company/api/venv/lib/python3.12/site-packages/sqlalchemy/ext/asyncio/session.py", line 461, in execute
    result = await greenlet_spawn(
             ^^^^^^^^^^^^^^^^^^^^^
  File "/home/dmytro/company/api/venv/lib/python3.12/site-packages/sqlalchemy/util/_concurrency_py3k.py", line 201, in greenlet_spawn
    result = context.throw(*sys.exc_info())
             ^^^^^^^^^^^^^^^^^^^^^^^^^^^^^^
  File "/home/dmytro/company/api/venv/lib/python3.12/site-packages/sqlalchemy/orm/session.py", line 2351, in execute
    return self._execute_internal(
           ^^^^^^^^^^^^^^^^^^^^^^^
  File "/home/dmytro/company/api/venv/lib/python3.12/site-packages/sqlalchemy/orm/session.py", line 2236, in _execute_internal
    result: Result[Any] = compile_state_cls.orm_execute_statement(
                          ^^^^^^^^^^^^^^^^^^^^^^^^^^^^^^^^^^^^^^^^
  File "/home/dmytro/company/api/venv/lib/python3.12/site-packages/sqlalchemy/orm/context.py", line 293, in orm_execute_statement
    result = conn.execute(
             ^^^^^^^^^^^^^
  File "/home/dmytro/company/api/venv/lib/python3.12/site-packages/sqlalchemy/engine/base.py", line 1418, in execute
    return meth(
           ^^^^^
  File "/home/dmytro/company/api/venv/lib/python3.12/site-packages/sqlalchemy/sql/elements.py", line 515, in _execute_on_connection
    return connection._execute_clauseelement(
           ^^^^^^^^^^^^^^^^^^^^^^^^^^^^^^^^^^
  File "/home/dmytro/company/api/venv/lib/python3.12/site-packages/sqlalchemy/engine/base.py", line 1640, in _execute_clauseelement
    ret = self._execute_context(
          ^^^^^^^^^^^^^^^^^^^^^^
  File "/home/dmytro/company/api/venv/lib/python3.12/site-packages/sqlalchemy/engine/base.py", line 1846, in _execute_context
    return self._exec_single_context(
           ^^^^^^^^^^^^^^^^^^^^^^^^^^
  File "/home/dmytro/company/api/venv/lib/python3.12/site-packages/sqlalchemy/engine/base.py", line 1986, in _exec_single_context
    self._handle_dbapi_exception(
  File "/home/dmytro/company/api/venv/lib/python3.12/site-packages/sqlalchemy/engine/base.py", line 2353, in _handle_dbapi_exception
    raise sqlalchemy_exception.with_traceback(exc_info[2]) from e
  File "/home/dmytro/company/api/venv/lib/python3.12/site-packages/sqlalchemy/engine/base.py", line 1967, in _exec_single_context
    self.dialect.do_execute(
  File "/home/dmytro/company/api/venv/lib/python3.12/site-packages/sqlalchemy/engine/default.py", line 924, in do_execute
    cursor.execute(statement, parameters)
  File "/home/dmytro/company/api/venv/lib/python3.12/site-packages/sqlalchemy/dialects/postgresql/asyncpg.py", line 572, in execute
    self._adapt_connection.await_(
  File "/home/dmytro/company/api/venv/lib/python3.12/site-packages/sqlalchemy/util/_concurrency_py3k.py", line 132, in await_only
    return current.parent.switch(awaitable)  # type: ignore[no-any-return,attr-defined] # noqa: E501
           ^^^^^^^^^^^^^^^^^^^^^^^^^^^^^^^^
  File "/home/dmytro/company/api/venv/lib/python3.12/site-packages/sqlalchemy/util/_concurrency_py3k.py", line 196, in greenlet_spawn
    value = await result
            ^^^^^^^^^^^^
  File "/home/dmytro/company/api/venv/lib/python3.12/site-packages/sqlalchemy/dialects/postgresql/asyncpg.py", line 550, in _prepare_and_execute
    self._handle_exception(error)
  File "/home/dmytro/company/api/venv/lib/python3.12/site-packages/sqlalchemy/dialects/postgresql/asyncpg.py", line 501, in _handle_exception
    self._adapt_connection._handle_exception(error)
  File "/home/dmytro/company/api/venv/lib/python3.12/site-packages/sqlalchemy/dialects/postgresql/asyncpg.py", line 784, in _handle_exception
    raise translated_error from error
sqlalchemy.exc.ProgrammingError: (sqlalchemy.dialects.postgresql.asyncpg.ProgrammingError) <class 'asyncpg.exceptions.InsufficientPrivilegeError'>: permission denied for table users
[SQL: SELECT users.id, users.email, users.user_name, users.password, users.avatar, users.created_at, users.verified, users.token_verify, users.refresh_token, users.role, users.blocked, users.password_changed, users.company_id, users.active, users.description 
FROM users 
WHERE users.email = $1::VARCHAR]
[parameters: ('nevojt@gmail.com',)]
(Background on this error at: https://sqlalche.me/e/20/f405)
