Traceback (most recent call last):
Traceback (most recent call last):

The above exception was the direct cause of the following exception:

Traceback (most recent call last):
  File "/home/dmytro/company/api/app/routers/user/auth.py", line 53, in login
    result = await db.execute(query)
             ^^^^^^^^^^^^^^^^^^^^^^^
  File "/home/dmytro/company/api/venv/lib/python3.12/site-packages/sqlalchemy/ext/asyncio/session.py", line 461, in execute
    result = await greenlet_spawn(
             ^^^^^^^^^^^^^^^^^^^^^
  File "/home/dmytro/company/api/venv/lib/python3.12/site-packages/sqlalchemy/orm/session.py", line 2351, in execute
    return self._execute_internal(
           ^^^^^^^^^^^^^^^^^^^^^^^
  File "/home/dmytro/company/api/venv/lib/python3.12/site-packages/sqlalchemy/orm/session.py", line 2236, in _execute_internal
    result: Result[Any] = compile_state_cls.orm_execute_statement(
                          ^^^^^^^^^^^^^^^^^^^^^^^^^^^^^^^^^^^^^^^^
  File "/home/dmytro/company/api/venv/lib/python3.12/site-packages/sqlalchemy/orm/context.py", line 293, in orm_execute_statement
    result = conn.execute(
             ^^^^^^^^^^^^^
  File "/home/dmytro/company/api/venv/lib/python3.12/site-packages/sqlalchemy/engine/base.py", line 1418, in execute
    return meth(
           ^^^^^
  File "/home/dmytro/company/api/venv/lib/python3.12/site-packages/sqlalchemy/sql/elements.py", line 515, in _execute_on_connection
    return connection._execute_clauseelement(
           ^^^^^^^^^^^^^^^^^^^^^^^^^^^^^^^^^^
                                                ^^^^^^^^^^^^^^^^^^^^^^
Traceback (most recent call last):
           ^^^^^^^^^^^^^^^^^^^^^^^^^^^^^^^^^^^^^^
Traceback (most recent call last):

The above exception was the direct cause of the following exception:

Traceback (most recent call last):
  File "/home/dmytro/company/api/app/routers/user/auth.py", line 53, in login
    result = await db.execute(query)
             ^^^^^^^^^^^^^^^^^^^^^^^
  File "/home/dmytro/company/api/venv/lib/python3.12/site-packages/sqlalchemy/ext/asyncio/session.py", line 461, in execute
    result = await greenlet_spawn(
             ^^^^^^^^^^^^^^^^^^^^^
  File "/home/dmytro/company/api/venv/lib/python3.12/site-packages/sqlalchemy/orm/session.py", line 2351, in execute
    return self._execute_internal(
           ^^^^^^^^^^^^^^^^^^^^^^^
  File "/home/dmytro/company/api/venv/lib/python3.12/site-packages/sqlalchemy/orm/session.py", line 2236, in _execute_internal
    result: Result[Any] = compile_state_cls.orm_execute_statement(
                          ^^^^^^^^^^^^^^^^^^^^^^^^^^^^^^^^^^^^^^^^
  File "/home/dmytro/company/api/venv/lib/python3.12/site-packages/sqlalchemy/orm/context.py", line 293, in orm_execute_statement
    result = conn.execute(
             ^^^^^^^^^^^^^
  File "/home/dmytro/company/api/venv/lib/python3.12/site-packages/sqlalchemy/engine/base.py", line 1418, in execute
    return meth(
           ^^^^^
  File "/home/dmytro/company/api/venv/lib/python3.12/site-packages/sqlalchemy/sql/elements.py", line 515, in _execute_on_connection
    return connection._execute_clauseelement(
           ^^^^^^^^^^^^^^^^^^^^^^^^^^^^^^^^^^
                                                ^^^^^^^^^^^^^^^^^^^^^^
           ^^^^^^^^^^^^^^^^^^^^^^^^^^^^^^^^^^^^^^
Traceback (most recent call last):

The above exception was the direct cause of the following exception:

Traceback (most recent call last):
  File "/home/dmytro/company/api/app/routers/user/auth.py", line 53, in login
    result = await db.execute(query)
             ^^^^^^^^^^^^^^^^^^^^^^^
  File "/home/dmytro/company/api/venv/lib/python3.12/site-packages/sqlalchemy/ext/asyncio/session.py", line 461, in execute
    result = await greenlet_spawn(
             ^^^^^^^^^^^^^^^^^^^^^
  File "/home/dmytro/company/api/venv/lib/python3.12/site-packages/sqlalchemy/orm/session.py", line 2351, in execute
    return self._execute_internal(
           ^^^^^^^^^^^^^^^^^^^^^^^
  File "/home/dmytro/company/api/venv/lib/python3.12/site-packages/sqlalchemy/orm/session.py", line 2236, in _execute_internal
    result: Result[Any] = compile_state_cls.orm_execute_statement(
                          ^^^^^^^^^^^^^^^^^^^^^^^^^^^^^^^^^^^^^^^^
  File "/home/dmytro/company/api/venv/lib/python3.12/site-packages/sqlalchemy/orm/context.py", line 293, in orm_execute_statement
    result = conn.execute(
             ^^^^^^^^^^^^^
  File "/home/dmytro/company/api/venv/lib/python3.12/site-packages/sqlalchemy/engine/base.py", line 1418, in execute
    return meth(
           ^^^^^
  File "/home/dmytro/company/api/venv/lib/python3.12/site-packages/sqlalchemy/sql/elements.py", line 515, in _execute_on_connection
    return connection._execute_clauseelement(
           ^^^^^^^^^^^^^^^^^^^^^^^^^^^^^^^^^^
                                                ^^^^^^^^^^^^^^^^^^^^^^
           ^^^^^^^^^^^^^^^^^^^^^^^^^^^^^^^^^^^^^^
Traceback (most recent call last):

The above exception was the direct cause of the following exception:

Traceback (most recent call last):
  File "/home/dmytro/company/api/app/routers/user/auth.py", line 53, in login
    result = await db.execute(query)
             ^^^^^^^^^^^^^^^^^^^^^^^
  File "/home/dmytro/company/api/venv/lib/python3.12/site-packages/sqlalchemy/ext/asyncio/session.py", line 461, in execute
    result = await greenlet_spawn(
             ^^^^^^^^^^^^^^^^^^^^^
  File "/home/dmytro/company/api/venv/lib/python3.12/site-packages/sqlalchemy/orm/session.py", line 2351, in execute
    return self._execute_internal(
           ^^^^^^^^^^^^^^^^^^^^^^^
  File "/home/dmytro/company/api/venv/lib/python3.12/site-packages/sqlalchemy/orm/session.py", line 2236, in _execute_internal
    result: Result[Any] = compile_state_cls.orm_execute_statement(
                          ^^^^^^^^^^^^^^^^^^^^^^^^^^^^^^^^^^^^^^^^
  File "/home/dmytro/company/api/venv/lib/python3.12/site-packages/sqlalchemy/orm/context.py", line 293, in orm_execute_statement
    result = conn.execute(
             ^^^^^^^^^^^^^
  File "/home/dmytro/company/api/venv/lib/python3.12/site-packages/sqlalchemy/engine/base.py", line 1418, in execute
    return meth(
           ^^^^^
  File "/home/dmytro/company/api/venv/lib/python3.12/site-packages/sqlalchemy/sql/elements.py", line 515, in _execute_on_connection
    return connection._execute_clauseelement(
           ^^^^^^^^^^^^^^^^^^^^^^^^^^^^^^^^^^
                                                ^^^^^^^^^^^^^^^^^^^^^^
           ^^^^^^^^^^^^^^^^^^^^^^^^^^^^^^^^^^^^^^
Traceback (most recent call last):

The above exception was the direct cause of the following exception:

Traceback (most recent call last):
  File "/home/dmytro/company/api/app/routers/user/auth.py", line 53, in login
    result = await db.execute(query)
             ^^^^^^^^^^^^^^^^^^^^^^^
  File "/home/dmytro/company/api/venv/lib/python3.12/site-packages/sqlalchemy/ext/asyncio/session.py", line 461, in execute
    result = await greenlet_spawn(
             ^^^^^^^^^^^^^^^^^^^^^
  File "/home/dmytro/company/api/venv/lib/python3.12/site-packages/sqlalchemy/orm/session.py", line 2351, in execute
    return self._execute_internal(
           ^^^^^^^^^^^^^^^^^^^^^^^
  File "/home/dmytro/company/api/venv/lib/python3.12/site-packages/sqlalchemy/orm/session.py", line 2236, in _execute_internal
    result: Result[Any] = compile_state_cls.orm_execute_statement(
                          ^^^^^^^^^^^^^^^^^^^^^^^^^^^^^^^^^^^^^^^^
  File "/home/dmytro/company/api/venv/lib/python3.12/site-packages/sqlalchemy/orm/context.py", line 293, in orm_execute_statement
    result = conn.execute(
             ^^^^^^^^^^^^^
  File "/home/dmytro/company/api/venv/lib/python3.12/site-packages/sqlalchemy/engine/base.py", line 1418, in execute
    return meth(
           ^^^^^
  File "/home/dmytro/company/api/venv/lib/python3.12/site-packages/sqlalchemy/sql/elements.py", line 515, in _execute_on_connection
    return connection._execute_clauseelement(
           ^^^^^^^^^^^^^^^^^^^^^^^^^^^^^^^^^^
                                                ^^^^^^^^^^^^^^^^^^^^^^
           ^^^^^^^^^^^^^^^^^^^^^^^^^^^^^^^^^^^^^^
Traceback (most recent call last):

The above exception was the direct cause of the following exception:

Traceback (most recent call last):
  File "/home/dmytro/company/api/app/routers/user/auth.py", line 53, in login
    result = await db.execute(query)
             ^^^^^^^^^^^^^^^^^^^^^^^
  File "/home/dmytro/company/api/venv/lib/python3.12/site-packages/sqlalchemy/ext/asyncio/session.py", line 461, in execute
    result = await greenlet_spawn(
             ^^^^^^^^^^^^^^^^^^^^^
  File "/home/dmytro/company/api/venv/lib/python3.12/site-packages/sqlalchemy/orm/session.py", line 2351, in execute
    return self._execute_internal(
           ^^^^^^^^^^^^^^^^^^^^^^^
  File "/home/dmytro/company/api/venv/lib/python3.12/site-packages/sqlalchemy/orm/session.py", line 2236, in _execute_internal
    result: Result[Any] = compile_state_cls.orm_execute_statement(
                          ^^^^^^^^^^^^^^^^^^^^^^^^^^^^^^^^^^^^^^^^
  File "/home/dmytro/company/api/venv/lib/python3.12/site-packages/sqlalchemy/orm/context.py", line 293, in orm_execute_statement
    result = conn.execute(
             ^^^^^^^^^^^^^
  File "/home/dmytro/company/api/venv/lib/python3.12/site-packages/sqlalchemy/engine/base.py", line 1418, in execute
    return meth(
           ^^^^^
  File "/home/dmytro/company/api/venv/lib/python3.12/site-packages/sqlalchemy/sql/elements.py", line 515, in _execute_on_connection
    return connection._execute_clauseelement(
           ^^^^^^^^^^^^^^^^^^^^^^^^^^^^^^^^^^
                                                ^^^^^^^^^^^^^^^^^^^^^^
           ^^^^^^^^^^^^^^^^^^^^^^^^^^^^^^^^^^^^^^
Traceback (most recent call last):

The above exception was the direct cause of the following exception:

Traceback (most recent call last):
  File "/home/dmytro/company/api/app/routers/user/auth.py", line 53, in login
    result = await db.execute(query)
             ^^^^^^^^^^^^^^^^^^^^^^^
  File "/home/dmytro/company/api/venv/lib/python3.12/site-packages/sqlalchemy/ext/asyncio/session.py", line 461, in execute
    result = await greenlet_spawn(
             ^^^^^^^^^^^^^^^^^^^^^
  File "/home/dmytro/company/api/venv/lib/python3.12/site-packages/sqlalchemy/orm/session.py", line 2351, in execute
    return self._execute_internal(
           ^^^^^^^^^^^^^^^^^^^^^^^
  File "/home/dmytro/company/api/venv/lib/python3.12/site-packages/sqlalchemy/orm/session.py", line 2236, in _execute_internal
    result: Result[Any] = compile_state_cls.orm_execute_statement(
                          ^^^^^^^^^^^^^^^^^^^^^^^^^^^^^^^^^^^^^^^^
  File "/home/dmytro/company/api/venv/lib/python3.12/site-packages/sqlalchemy/orm/context.py", line 293, in orm_execute_statement
    result = conn.execute(
             ^^^^^^^^^^^^^
  File "/home/dmytro/company/api/venv/lib/python3.12/site-packages/sqlalchemy/engine/base.py", line 1418, in execute
    return meth(
           ^^^^^
  File "/home/dmytro/company/api/venv/lib/python3.12/site-packages/sqlalchemy/sql/elements.py", line 515, in _execute_on_connection
    return connection._execute_clauseelement(
           ^^^^^^^^^^^^^^^^^^^^^^^^^^^^^^^^^^
                                                ^^^^^^^^^^^^^^^^^^^^^^
